Workbook

Sheet customer_data
A1: Customer ID | B1: Full Name | C1: Email | D1: Phone | E1: City | F1: State | G1: Signup Date | H1: Total Purchases | I1: Membership Tier | J1: Email (Normalized) | K1: Name (Normalised) | L1: Email Match Count | M1: Name Match Count | N1: Review Flag | O1: City (Cleaned) | P1: Phone (normalized) | Q1: Phone Match Count
A2: CUST0001 | B2: Diya Rao | C2: diya.rao1@example.com | D2: NotProvided | E2: Jaipur | F2: Rajasthan | G2: 45544 | H2: 18267 | I2: Gold | J2: =TRIM(LOWER(customer_data!$C2)) -> diya.rao1@example.com | K2: =TRIM(PROPER(customer_data!$B2)) -> Diya Rao | L2: =COUNTIF($J$2:$J$36, J2) -> 1 | M2: =COUNTIF($K$2:$K$36, K2) -> 1 | N2: =IF(OR(L2>1,M2>1),"Review","OK") -> OK | O2: =PROPER(TRIM(E2)) -> Jaipur | P2: {=D2:D36} -> NotProvided | Q2: =COUNTIF($P:$P,P2) -> 6
A3: CUST0002 | B3: Ananya Bhatt | C3: ananya.bhatt2@example.com | D3: 9177981439 | E3: Ahmedabad | F3: Gujarat | G3: 45602 | H3: 31080 | I3: Platinum | J3: =TRIM(LOWER(customer_data!$C3)) -> ananya.bhatt2@example.com | K3: =TRIM(PROPER(customer_data!$B3)) -> Ananya Bhatt | L3: =COUNTIF($J$2:$J$36, J3) -> 1 | M3: =COUNTIF($K$2:$K$36, K3) -> 2 | N3: =IF(OR(L3>1,M3>1),"Review","OK") -> Review | O3: =PROPER(TRIM(E3)) -> Ahmedabad | P3: 9177981439 | Q3: =COUNTIF($P:$P,P3) -> 1
A4: CUST0003 | B4: Arjun Chauhan | C4: arjun.chauhan3@example.com | D4: 9227130570 | E4: Chennai | F4: Tamil Nadu | G4: 45520 | H4: 21186 | I4: Gold | J4: =TRIM(LOWER(customer_data!$C4)) -> arjun.chauhan3@example.com | K4: =TRIM(PROPER(customer_data!$B4)) -> Arjun Chauhan | L4: =COUNTIF($J$2:$J$36, J4) -> 2 | M4: =COUNTIF($K$2:$K$36, K4) -> 2 | N4: =IF(OR(L4>1,M4>1),"Review","OK") -> Review | O4: =PROPER(TRIM(E4)) -> Chennai | P4: 9227130570 | Q4: =COUNTIF($P:$P,P4) -> 2
A5: CUST0004 | B5: Isha Reddy | C5: isha.reddy4@example.com | D5: 9487266582 | E5: Jaipur | F5: Rajasthan | G5: 45445 | H5: 11054 | I5: Gold | J5: =TRIM(LOWER(customer_data!$C5)) -> isha.reddy4@example.com | K5: =TRIM(PROPER(customer_data!$B5)) -> Isha Reddy | L5: =COUNTIF($J$2:$J$36, J5) -> 1 | M5: =COUNTIF($K$2:$K$36, K5) -> 1 | N5: =IF(OR(L5>1,M5>1),"Review","OK") -> OK | O5: =PROPER(TRIM(E5)) -> Jaipur | P5: 9487266582 | Q5: =COUNTIF($P:$P,P5) -> 1
A6: CUST0005 | B6: Ishaan Sharma | C6: ishaan.sharma5@example.com | D6: NotProvided | E6: PUNE | F6: Maharashtra | G6: 45417 | H6: 39482 | I6: Gold | J6: =TRIM(LOWER(customer_data!$C6)) -> ishaan.sharma5@example.com | K6: =TRIM(PROPER(customer_data!$B6)) -> Ishaan Sharma | L6: =COUNTIF($J$2:$J$36, J6) -> 1 | M6: =COUNTIF($K$2:$K$36, K6) -> 1 | N6: =IF(OR(L6>1,M6>1),"Review","OK") -> OK | O6: =PROPER(TRIM(E6)) -> Pune | P6: NotProvided | Q6: =COUNTIF($P:$P,P6) -> 6
A7: CUST0006 | B7: Aarav Verma | C7: aarav.verma6@example.com | D7: 9394263945 | E7: Bengaluru | F7: Karnataka | G7: 46166 | H7: 25526 | I7: Platinum | J7: =TRIM(LOWER(customer_data!$C7)) -> aarav.verma6@example.com | K7: =TRIM(PROPER(customer_data!$B7)) -> Aarav Verma | L7: =COUNTIF($J$2:$J$36, J7) -> 2 | M7: =COUNTIF($K$2:$K$36, K7) -> 2 | N7: =IF(OR(L7>1,M7>1),"Review","OK") -> Review | O7: =PROPER(TRIM(E7)) -> Bengaluru | P7: 9394263945 | Q7: =COUNTIF($P:$P,P7) -> 2
A8: CUST0007 | B8: Aditya Das | C8: aditya.das7@example.com | D8: 9752331677 | E8: Unknown | F8: Maharashtra | G8: 46185 | H8: 42499 | I8: Bronze | J8: =TRIM(LOWER(customer_data!$C8)) -> aditya.das7@example.com | K8: =TRIM(PROPER(customer_data!$B8)) -> Aditya Das | L8: =COUNTIF($J$2:$J$36, J8) -> 1 | M8: =COUNTIF($K$2:$K$36, K8) -> 1 | N8: =IF(OR(L8>1,M8>1),"Review","OK") -> OK | O8: =PROPER(TRIM(E8)) -> Unknown | P8: 9752331677 | Q8: =COUNTIF($P:$P,P8) -> 1
A9: CUST0008 | B9: Aditya Rao | C9: aditya.rao8@example.com | D9: 9784421408 | E9: Hyderabad | F9: Telangana | G9: 45477 | H9: 6704 | I9: Platinum | J9: =TRIM(LOWER(customer_data!$C9)) -> aditya.rao8@example.com | K9: =TRIM(PROPER(customer_data!$B9)) -> Aditya Rao | L9: =COUNTIF($J$2:$J$36, J9) -> 1 | M9: =COUNTIF($K$2:$K$36, K9) -> 1 | N9: =IF(OR(L9>1,M9>1),"Review","OK") -> OK | O9: =PROPER(TRIM(E9)) -> Hyderabad | P9: 9784421408 | Q9: =COUNTIF($P:$P,P9) -> 1
A10: CUST0009 | B10: Siddharth Kapoor | C10: siddharth.kapoor9@example.com | D10: NotProvided | E10: Chennai | F10: Tamil Nadu | G10: 45755 | H10: 41402 | I10: Silver | J10: =TRIM(LOWER(customer_data!$C10)) -> siddharth.kapoor9@example.com | K10: =TRIM(PROPER(customer_data!$B10)) -> Siddharth Kapoor | L10: =COUNTIF($J$2:$J$36, J10) -> 1 | M10: =COUNTIF($K$2:$K$36, K10) -> 2 | N10: =IF(OR(L10>1,M10>1),"Review","OK") -> Review | O10: =PROPER(TRIM(E10)) -> Chennai | P10: NotProvided | Q10: =COUNTIF($P:$P,P10) -> 6
A11: CUST0010 | B11: Pooja Chauhan | C11: Not Provided | D11: NotProvided | E11: Unknown | F11: Rajasthan | G11: 45552 | H11: 7212 | I11: Bronze | J11: =TRIM(LOWER(customer_data!$C11)) -> not provided | K11: =TRIM(PROPER(customer_data!$B11)) -> Pooja Chauhan | L11: =COUNTIF($J$2:$J$36, J11) -> 6 | M11: =COUNTIF($K$2:$K$36, K11) -> 1 | N11: =IF(OR(L11>1,M11>1),"Review","OK") -> Review | O11: =PROPER(TRIM(E11)) -> Unknown | P11: NotProvided | Q11: =COUNTIF($P:$P,P11) -> 6
A12: CUST0011 | B12: Nikhil Verma | C12: Not Provided | D12: 9399178390 | E12: CHENNAI | F12: Tamil Nadu | G12: 45413 | H12: 2334 | I12: Silver | J12: =TRIM(LOWER(customer_data!$C12)) -> not provided | K12: =TRIM(PROPER(customer_data!$B12)) -> Nikhil Verma | L12: =COUNTIF($J$2:$J$36, J12) -> 6 | M12: =COUNTIF($K$2:$K$36, K12) -> 1 | N12: =IF(OR(L12>1,M12>1),"Review","OK") -> Review | O12: =PROPER(TRIM(E12)) -> Chennai | P12: 9399178390 | Q12: =COUNTIF($P:$P,P12) -> 1
A13: CUST0012 | B13: Anika Gupta | C13: Not Provided | D13: 9222271940 | E13: Jaipur | F13: Rajasthan | G13: 45892 | H13: 6593 | I13: Platinum | J13: =TRIM(LOWER(customer_data!$C13)) -> not provided | K13: =TRIM(PROPER(customer_data!$B13)) -> Anika Gupta | L13: =COUNTIF($J$2:$J$36, J13) -> 6 | M13: =COUNTIF($K$2:$K$36, K13) -> 2 | N13: =IF(OR(L13>1,M13>1),"Review","OK") -> Review | O13: =PROPER(TRIM(E13)) -> Jaipur | P13: 9222271940 | Q13: =COUNTIF($P:$P,P13) -> 2
A14: CUST0013 | B14: Pooja Kapoor | C14: pooja.kapoor13@example.com | D14: 9280788920 | E14: Jaipur | F14: Rajasthan | G14: 45687 | H14: 30329 | I14: Gold | J14: =TRIM(LOWER(customer_data!$C14)) -> pooja.kapoor13@example.com | K14: =TRIM(PROPER(customer_data!$B14)) -> Pooja Kapoor | L14: =COUNTIF($J$2:$J$36, J14) -> 1 | M14: =COUNTIF($K$2:$K$36, K14) -> 1 | N14: =IF(OR(L14>1,M14>1),"Review","OK") -> OK | O14: =PROPER(TRIM(E14)) -> Jaipur | P14: 9280788920 | Q14: =COUNTIF($P:$P,P14) -> 1
A15: CUST0014 | B15: Pooja Das | C15: pooja.das14@example.com | D15: 9569270901 | E15: Kolkata | F15: West Bengal | G15: 45901 | H15: -6716 | I15: Gold | J15: =TRIM(LOWER(customer_data!$C15)) -> pooja.das14@example.com | K15: =TRIM(PROPER(customer_data!$B15)) -> Pooja Das | L15: =COUNTIF($J$2:$J$36, J15) -> 1 | M15: =COUNTIF($K$2:$K$36, K15) -> 1 | N15: =IF(OR(L15>1,M15>1),"Review","OK") -> OK | O15: =PROPER(TRIM(E15)) -> Kolkata | P15: 9569270901 | Q15: =COUNTIF($P:$P,P15) -> 1
A16: CUST0015 | B16: Pooja Gupta | C16: Not Provided | D16: 9353685823 | E16: Ahmedabad | F16: Gujarat | G16: 46178 | H16: -40828 | I16: Platinum | J16: =TRIM(LOWER(customer_data!$C16)) -> not provided | K16: =TRIM(PROPER(customer_data!$B16)) -> Pooja Gupta | L16: =COUNTIF($J$2:$J$36, J16) -> 6 | M16: =COUNTIF($K$2:$K$36, K16) -> 2 | N16: =IF(OR(L16>1,M16>1),"Review","OK") -> Review | O16: =PROPER(TRIM(E16)) -> Ahmedabad | P16: 9353685823 | Q16: =COUNTIF($P:$P,P16) -> 2
A17: CUST0016 | B17: Aditi Rao | C17: aditi.rao16@example.com | D17: 9253863931 | E17: Ahmedabad | F17: Gujarat | G17: 46012 | H17: 17984 | I17: Platinum | J17: =TRIM(LOWER(customer_data!$C17)) -> aditi.rao16@example.com | K17: =TRIM(PROPER(customer_data!$B17)) -> Aditi Rao | L17: =COUNTIF($J$2:$J$36, J17) -> 1 | M17: =COUNTIF($K$2:$K$36, K17) -> 1 | N17: =IF(OR(L17>1,M17>1),"Review","OK") -> OK | O17: =PROPER(TRIM(E17)) -> Ahmedabad | P17: 9253863931 | Q17: =COUNTIF($P:$P,P17) -> 1
A18: CUST0017 | B18: Aarav Joshi | C18: aarav.joshi17@example.com | D18: 9856873800 | E18: Kolkata | F18: West Bengal | G18: 45725 | H18: 1862 | I18: Gold | J18: =TRIM(LOWER(customer_data!$C18)) -> aarav.joshi17@example.com | K18: =TRIM(PROPER(customer_data!$B18)) -> Aarav Joshi | L18: =COUNTIF($J$2:$J$36, J18) -> 1 | M18: =COUNTIF($K$2:$K$36, K18) -> 1 | N18: =IF(OR(L18>1,M18>1),"Review","OK") -> OK | O18: =PROPER(TRIM(E18)) -> Kolkata | P18: 9856873800 | Q18: =COUNTIF($P:$P,P18) -> 1
A19: CUST0018 | B19: Devansh Rao | C19: devansh.rao18@example.com | D19: 9495084811 | E19: Ahmedabad | F19: Gujarat | G19: 45561 | H19: 23804 | I19: Gold | J19: =TRIM(LOWER(customer_data!$C19)) -> devansh.rao18@example.com | K19: =TRIM(PROPER(customer_data!$B19)) -> Devansh Rao | L19: =COUNTIF($J$2:$J$36, J19) -> 1 | M19: =COUNTIF($K$2:$K$36, K19) -> 1 | N19: =IF(OR(L19>1,M19>1),"Review","OK") -> OK | O19: =PROPER(TRIM(E19)) -> Ahmedabad | P19: 9495084811 | Q19: =COUNTIF($P:$P,P19) -> 1
A20: CUST0019 | B20: Siddharth Patel | C20: siddharth.patel19@example.com | D20: NotProvided | E20: Jaipur | F20: Rajasthan | G20: 45772 | H20: 17282 | I20: Bronze | J20: =TRIM(LOWER(customer_data!$C20)) -> siddharth.patel19@example.com | K20: =TRIM(PROPER(customer_data!$B20)) -> Siddharth Patel | L20: =COUNTIF($J$2:$J$36, J20) -> 1 | M20: =COUNTIF($K$2:$K$36, K20) -> 1 | N20: =IF(OR(L20>1,M20>1),"Review","OK") -> OK | O20: =PROPER(TRIM(E20)) -> Jaipur | P20: NotProvided | Q20: =COUNTIF($P:$P,P20) -> 6
A21: CUST0020 | B21: Arjun Verma | C21: arjun.verma20@example.com | D21: 9137343472 | E21: bengaluru | F21: Karnataka | G21: 45611 | H21: 2150 | I21: Bronze | J21: =TRIM(LOWER(customer_data!$C21)) -> arjun.verma20@example.com | K21: =TRIM(PROPER(customer_data!$B21)) -> Arjun Verma | L21: =COUNTIF($J$2:$J$36, J21) -> 1 | M21: =COUNTIF($K$2:$K$36, K21) -> 1 | N21: =IF(OR(L21>1,M21>1),"Review","OK") -> OK | O21: =PROPER(TRIM(E21)) -> Bengaluru | P21: 9137343472 | Q21: =COUNTIF($P:$P,P21) -> 1
A22: CUST0021 | B22: Aditya Menon | C22: aditya.menon21@example.com | D22: 9403422179 | E22: jaipur | F22: Rajasthan | G22: 46115 | H22: 23979 | I22: Gold | J22: =TRIM(LOWER(customer_data!$C22)) -> aditya.menon21@example.com | K22: =TRIM(PROPER(customer_data!$B22)) -> Aditya Menon | L22: =COUNTIF($J$2:$J$36, J22) -> 1 | M22: =COUNTIF($K$2:$K$36, K22) -> 1 | N22: =IF(OR(L22>1,M22>1),"Review","OK") -> OK | O22: =PROPER(TRIM(E22)) -> Jaipur | P22: 9403422179 | Q22: =COUNTIF($P:$P,P22) -> 1
A23: CUST0022 | B23: Diya Sharma | C23: diya.sharma22@example.com | D23: 9256982268 | E23: Bengaluru | F23: Karnataka | G23: 45293 | H23: 15575 | I23: Gold | J23: =TRIM(LOWER(customer_data!$C23)) -> diya.sharma22@example.com | K23: =TRIM(PROPER(customer_data!$B23)) -> Diya Sharma | L23: =COUNTIF($J$2:$J$36, J23) -> 1 | M23: =COUNTIF($K$2:$K$36, K23) -> 1 | N23: =IF(OR(L23>1,M23>1),"Review","OK") -> OK | O23: =PROPER(TRIM(E23)) -> Bengaluru | P23: 9256982268 | Q23: =COUNTIF($P:$P,P23) -> 1
A24: CUST0023 | B24: Simran Menon | C24: simran.menon23@example.com | D24: 9384054524 | E24: Unknown | F24: Delhi | G24: 45546 | H24: 14121 | I24: Gold | J24: =TRIM(LOWER(customer_data!$C24)) -> simran.menon23@example.com | K24: =TRIM(PROPER(customer_data!$B24)) -> Simran Menon | L24: =COUNTIF($J$2:$J$36, J24) -> 2 | M24: =COUNTIF($K$2:$K$36, K24) -> 2 | N24: =IF(OR(L24>1,M24>1),"Review","OK") -> Review | O24: =PROPER(TRIM(E24)) -> Unknown | P24: 9384054524 | Q24: =COUNTIF($P:$P,P24) -> 2
A25: CUST0024 | B25: Ananya Bhatt | C25: Not Provided | D25: 9917749035 | E25: Hyderabad | F25: Telangana | G25: 45324 | H25: 37273 | I25: Silver | J25: =TRIM(LOWER(customer_data!$C25)) -> not provided | K25: =TRIM(PROPER(customer_data!$B25)) -> Ananya Bhatt | L25: =COUNTIF($J$2:$J$36, J25) -> 6 | M25: =COUNTIF($K$2:$K$36, K25) -> 2 | N25: =IF(OR(L25>1,M25>1),"Review","OK") -> Review | O25: =PROPER(TRIM(E25)) -> Hyderabad | P25: 9917749035 | Q25: =COUNTIF($P:$P,P25) -> 1
A26: CUST0025 | B26: Siddharth Kapoor | C26: siddharth.kapoor25@example.com | D26: 9311880275 | E26: Unknown | F26: Telangana | G26: 45794 | H26: 25673 | I26: Silver | J26: =TRIM(LOWER(customer_data!$C26)) -> siddharth.kapoor25@example.com | K26: =TRIM(PROPER(customer_data!$B26)) -> Siddharth Kapoor | L26: =COUNTIF($J$2:$J$36, J26) -> 1 | M26: =COUNTIF($K$2:$K$36, K26) -> 2 | N26: =IF(OR(L26>1,M26>1),"Review","OK") -> Review | O26: =PROPER(TRIM(E26)) -> Unknown | P26: 9311880275 | Q26: =COUNTIF($P:$P,P26) -> 1
A27: CUST0026 | B27: Arjun Menon | C27: arjun.menon26@example.com | D27: NotProvided | E27: hyderabad | F27: Telangana | G27: 45791 | H27: 40656 | I27: Bronze | J27: =TRIM(LOWER(customer_data!$C27)) -> arjun.menon26@example.com | K27: =TRIM(PROPER(customer_data!$B27)) -> Arjun Menon | L27: =COUNTIF($J$2:$J$36, J27) -> 1 | M27: =COUNTIF($K$2:$K$36, K27) -> 1 | N27: =IF(OR(L27>1,M27>1),"Review","OK") -> OK | O27: =PROPER(TRIM(E27)) -> Hyderabad | P27: NotProvided | Q27: =COUNTIF($P:$P,P27) -> 6
A28: CUST0027 | B28: Rohan Kapoor | C28: rohan.kapoor27@example.com | D28: 9561072854 | E28: Ahmedabad | F28: Gujarat | G28: 46084 | H28: 22745 | I28: Bronze | J28: =TRIM(LOWER(customer_data!$C28)) -> rohan.kapoor27@example.com | K28: =TRIM(PROPER(customer_data!$B28)) -> Rohan Kapoor | L28: =COUNTIF($J$2:$J$36, J28) -> 1 | M28: =COUNTIF($K$2:$K$36, K28) -> 1 | N28: =IF(OR(L28>1,M28>1),"Review","OK") -> OK | O28: =PROPER(TRIM(E28)) -> Ahmedabad | P28: 9561072854 | Q28: =COUNTIF($P:$P,P28) -> 1
A29: CUST0028 | B29: Sneha Chauhan | C29: sneha.chauhan28@example.com | D29: 9210859664 | E29: Delhi | F29: Delhi | G29: 45497 | H29: 4075 | I29: Silver | J29: =TRIM(LOWER(customer_data!$C29)) -> sneha.chauhan28@example.com | K29: =TRIM(PROPER(customer_data!$B29)) -> Sneha Chauhan | L29: =COUNTIF($J$2:$J$36, J29) -> 1 | M29: =COUNTIF($K$2:$K$36, K29) -> 1 | N29: =IF(OR(L29>1,M29>1),"Review","OK") -> OK | O29: =PROPER(TRIM(E29)) -> Delhi | P29: 9210859664 | Q29: =COUNTIF($P:$P,P29) -> 1
A30: CUST0029 | B30: Meera Reddy | C30: meera.reddy29@example.com | D30: 9622942419 | E30: Ahmedabad | F30: Gujarat | G30: 45420 | H30: 36196 | I30: Platinum | J30: =TRIM(LOWER(customer_data!$C30)) -> meera.reddy29@example.com | K30: =TRIM(PROPER(customer_data!$B30)) -> Meera Reddy | L30: =COUNTIF($J$2:$J$36, J30) -> 1 | M30: =COUNTIF($K$2:$K$36, K30) -> 1 | N30: =IF(OR(L30>1,M30>1),"Review","OK") -> OK | O30: =PROPER(TRIM(E30)) -> Ahmedabad | P30: 9622942419 | Q30: =COUNTIF($P:$P,P30) -> 1
A31: CUST0030 | B31: Vivaan Chauhan | C31: Not Provided | D31: 9214210330 | E31: Chennai | F31: Tamil Nadu | G31: 46012 | H31: 24656 | I31: Platinum | J31: =TRIM(LOWER(customer_data!$C31)) -> not provided | K31: =TRIM(PROPER(customer_data!$B31)) -> Vivaan Chauhan | L31: =COUNTIF($J$2:$J$36, J31) -> 6 | M31: =COUNTIF($K$2:$K$36, K31) -> 1 | N31: =IF(OR(L31>1,M31>1),"Review","OK") -> Review | O31: =PROPER(TRIM(E31)) -> Chennai | P31: 9214210330 | Q31: =COUNTIF($P:$P,P31) -> 1
A32: CUST0031 | B32: Arjun Chauhan | C32: arjun.chauhan3@example.com | D32: 9227130570 | E32: Chennai | F32: Tamil Nadu | G32: 45520 | H32: 21186 | I32: Gold | J32: =TRIM(LOWER(customer_data!$C32)) -> arjun.chauhan3@example.com | K32: =TRIM(PROPER(customer_data!$B32)) -> Arjun Chauhan | L32: =COUNTIF($J$2:$J$36, J32) -> 2 | M32: =COUNTIF($K$2:$K$36, K32) -> 2 | N32: =IF(OR(L32>1,M32>1),"Review","OK") -> Review | O32: =PROPER(TRIM(E32)) -> Chennai | P32: 9227130570 | Q32: =COUNTIF($P:$P,P32) -> 2
A33: CUST0032 | B33: Simran Menon | C33: simran.menon23@example.com | D33: 9384054524 | E33: Delhi | F33: Delhi | G33: 45546 | H33: 14121 | I33: Gold | J33: =TRIM(LOWER(customer_data!$C33)) -> simran.menon23@example.com | K33: =TRIM(PROPER(customer_data!$B33)) -> Simran Menon | L33: =COUNTIF($J$2:$J$36, J33) -> 2 | M33: =COUNTIF($K$2:$K$36, K33) -> 2 | N33: =IF(OR(L33>1,M33>1),"Review","OK") -> Review | O33: =PROPER(TRIM(E33)) -> Delhi | P33: 9384054524 | Q33: =COUNTIF($P:$P,P33) -> 2
A34: CUST0033 | B34: Aarav Verma | C34: aarav.verma6@example.com | D34: 9394263945 | E34: Bengaluru | F34: Karnataka | G34: 46166 | H34: 25526 | I34: Platinum | J34: =TRIM(LOWER(customer_data!$C34)) -> aarav.verma6@example.com | K34: =TRIM(PROPER(customer_data!$B34)) -> Aarav Verma | L34: =COUNTIF($J$2:$J$36, J34) -> 2 | M34: =COUNTIF($K$2:$K$36, K34) -> 2 | N34: =IF(OR(L34>1,M34>1),"Review","OK") -> Review | O34: =PROPER(TRIM(E34)) -> Bengaluru | P34: 9394263945 | Q34: =COUNTIF($P:$P,P34) -> 2
A35: CUST0034 | B35: Anika Gupta | C35: anika.gupta12@example.com | D35: 9222271940 | E35: Jaipur | F35: Rajasthan | G35: 45892 | H35: 6593 | I35: Platinum | J35: =TRIM(LOWER(customer_data!$C35)) -> anika.gupta12@example.com | K35: =TRIM(PROPER(customer_data!$B35)) -> Anika Gupta | L35: =COUNTIF($J$2:$J$36, J35) -> 1 | M35: =COUNTIF($K$2:$K$36, K35) -> 2 | N35: =IF(OR(L35>1,M35>1),"Review","OK") -> Review | O35: =PROPER(TRIM(E35)) -> Jaipur | P35: 9222271940 | Q35: =COUNTIF($P:$P,P35) -> 2
A36: CUST0035 | B36: Pooja Gupta | C36: POOJA.GUPTA15@EXAMPLE.COM | D36: 9353685823 | E36: Ahmedabad | F36: Gujarat | G36: 46178 | H36: 40828 | I36: Platinum | J36: =TRIM(LOWER(customer_data!$C36)) -> pooja.gupta15@example.com | K36: =TRIM(PROPER(customer_data!$B36)) -> Pooja Gupta | L36: =COUNTIF($J$2:$J$36, J36) -> 1 | M36: =COUNTIF($K$2:$K$36, K36) -> 2 | N36: =IF(OR(L36>1,M36>1),"Review","OK") -> Review | O36: =PROPER(TRIM(E36)) -> Ahmedabad | P36: 9353685823 | Q36: =COUNTIF($P:$P,P36) -> 2
N41: Part B: Q.7
C42: Blank Email | D42: =COUNTBLANK(J2:J36) -> 0 | N42: Remove Duplicates only deletes records that are exactly the same, so if any value is different (even an extra space, different spelling, or formatting), Excel treats it as a different record and does not remove it.
C43: Blank Ph | D43: =COUNTBLANK(D2:D36) -> 0
C44: Blank City | D44: =COUNTBLANK(E2:E36) -> 0
...

Sheet summary
A2: Data Quality ScoreCard
D6: Metric | E6: Formula/Value
D7: Total Rows Imported | E7: 40
D8: Exact Duplicates Removed | E8: =E7-COUNTA(customer_data!A2:A36) -> 5
D9: Near Duplicates Resolved | E9: =E7-E8 -> 35
D10: Final Row Count | E10: =COUNTA(customer_data!A2:A36) -> 35
D11: Blank Emails Filled | E11: =COUNTIF(customer_data!J2:J36, "not provided") -> 6
D12: Blank Ph Filled | E12: =COUNTIF(customer_data!D2:D36, "NotProvided") -> 6
D13: Blank City Filled | E13: =COUNTIF(customer_data!E2:E36, "Unknown") -> 4
D14: Invalid Purchase Values | E14: =COUNTIF(customer_data!H2:H36, "<0" ) -> 2

Sheet state_summary
A1: State | B1: Customer Count | C1: Total Purchase
A2: Rajasthan | B2: =COUNTIF(customer_data!$F$2:$F$36,A2) -> 8 | C2: =SUMIF(customer_data!$F$2:$F$36,A2,customer_data!$H$2:$H$36) -> 121309
A3: Gujarat | B3: =COUNTIF(customer_data!$F$2:$F$36,A3) -> 7 | C3: =SUMIF(customer_data!$F$2:$F$36,A3,customer_data!$H$2:$H$36) -> 131809
A4: Tamil Nadu | B4: =COUNTIF(customer_data!$F$2:$F$36,A4) -> 5 | C4: =SUMIF(customer_data!$F$2:$F$36,A4,customer_data!$H$2:$H$36) -> 110764
A5: Karnataka | B5: =COUNTIF(customer_data!$F$2:$F$36,A5) -> 4 | C5: =SUMIF(customer_data!$F$2:$F$36,A5,customer_data!$H$2:$H$36) -> 68777
A6: Maharashtra | B6: =COUNTIF(customer_data!$F$2:$F$36,A6) -> 2 | C6: =SUMIF(customer_data!$F$2:$F$36,A6,customer_data!$H$2:$H$36) -> 81981
A7: Telangana | B7: =COUNTIF(customer_data!$F$2:$F$36,A7) -> 4 | C7: =SUMIF(customer_data!$F$2:$F$36,A7,customer_data!$H$2:$H$36) -> 110306
A8: West Bengal | B8: =COUNTIF(customer_data!$F$2:$F$36,A8) -> 2 | C8: =SUMIF(customer_data!$F$2:$F$36,A8,customer_data!$H$2:$H$36) -> -4854
A9: Delhi | B9: =COUNTIF(customer_data!$F$2:$F$36,A9) -> 3 | C9: =SUMIF(customer_data!$F$2:$F$36,A9,customer_data!$H$2:$H$36) -> 32317
